<mujoco model="diffdrive">
  <option gravity="0 0 -9.81"/>
  <worldbody>
    <light diffuse=".5 .5 .5" pos="0 0 300" dir="0 0 -1"/>
    <geom type="plane" size="25 5 0.1" rgba=".9 .9 .9 1"/>
    <!--differential drive robot-->
    <body name="chassis" pos="-24 0 .2" euler="0 90 0">
      <joint type="free" name="chassis"/>
      <geom type="box" size=".05 .2 .3" rgba=".9 0 0 1"/>
      <site name="marker" pos="0 0 0.1" size=".1"/>
      <body name="right-wheel" pos="0 -0.3 0.3" euler="90 0 0">
        <joint name="right-wheel" type="hinge" axis="0 0 -1"/>
        <geom type="cylinder" size=".2 .05" rgba="0 0 0 1"/>
      </body>
      <body name="left-wheel" pos="0 0.3 0.3" euler="90 0 0">
        <joint name="left-wheel" type="hinge" axis="0 0 -1"/>
        <geom type="cylinder" size=".2 .05" rgba="0 0 0 1"/>
      </body>
    </body>
    <!--goal line/box-->
    <body name="goal" pos="24.5 0 .3">
      <geom type="box" size=".5 .5 .5" rgba=".9 0 0 1"/>
    </body>
    <!--walls-->
    <body name="wall">
      <geom name="wall_1" type="box" size="25 .5 .5" pos="0 4.5 0" rgba=".2 .2 .2 1"/>
      <geom name="wall_2" type="box" size="25 .5 .5" pos="0 -4.5 0" rgba=".2 .2 .2 1"/>
      <geom name="wall_3" type="box" size=".5 5 .5" pos="25.5 0 0" rgba=".2 .2 .2 1"/>
      <geom name="wall_4" type="box" size=".5 5 .5" pos="-25.5 0 0" rgba=".2 .2 .2 1"/>
    </body>
  </worldbody>
  <actuator>
    <velocity name="left-velocity-servo" joint="left-wheel" kv="100"/>
    <velocity name="right-velocity-servo" joint="right-wheel" kv="100"/>
  </actuator>
</mujoco>
